<?xml version="1.0" ?>
<!-- =================================================================================== -->
<!-- |    This document was autogenerated by xacro from dobot_hex.xacro              | -->
<!-- |    EDITING THIS FILE BY HAND IS NOT RECOMMENDED                                 | -->
<!-- =================================================================================== -->
<robot name="dobot_hex">
  <mujoco>
    <compiler balanceinertia="true" discardvisual="false" meshdir="../meshes/"/>
  </mujoco>
  <link name="world">
</link>
  <link name="link_trunk">
    <inertial>
      <origin rpy="0 0 0" xyz="0.010889 0.0 0.002427"/>
      <mass value="9.659"/>
      <inertia ixx="55062.22E-06" ixy="-36.04E-06" ixz="8679.7E-06" iyy="309879.53E-06" iyz="61.463E-06" izz="335289.14E-06"/>
    </inertial>
    <visual>
      <origin rpy="0 0 0" xyz="0 0 0"/>
      <geometry>
        <mesh filename="package://dobot_hex/meshes/trunk.STL"/>
      </geometry>
      <material name="">
        <color rgba="0.752941176470588 0.752941176470588 0.752941176470588 1"/>
      </material>
    </visual>
    <collision>
      <origin rpy="0 0 0" xyz="0 0 0"/>
      <geometry>
        <box size="0.5 0.1275 0.1"/>
      </geometry>
      <material>
        <color rgba="1.0 0.0 0.0 0.5"/>
      </material>
    </collision>
  </link>
  <joint name="joint_fixed_world" type="fixed">
    <origin rpy="0 0 0" xyz="0 0 0"/>
    <parent link="world"/>
    <child link="link_trunk"/>
  </joint>
  <link name="link_front_left_hip">
    <inertial>
      <origin rpy="0 0 0" xyz="-0.00249 0.00198 0.000018"/>
      <mass value="0.506"/>
      <inertia ixx="162.713E-06" ixy="-1.271e-05" ixz="0.0" iyy="293.236E-06" iyz="0.0" izz="258.577E-06"/>
    </inertial>
    <visual>
      <origin rpy="0 0 0" xyz="0 0 0"/>
      <geometry>
        <mesh filename="package://dobot_hex/meshes/hip.STL"/>
      </geometry>
      <material name="">
        <color rgba="0.752941176470588 0.752941176470588 0.752941176470588 1"/>
      </material>
    </visual>
    <collision>
      <origin rpy="1.5708 0 0" xyz="0 0.08 0"/>
      <geometry>
        <cylinder length="0.04" radius="0.048"/>
      </geometry>
    </collision>
  </link>
  <joint name="joint_front_left_abad" type="revolute">
    <origin rpy="0 0 0" xyz="0.3003 0.05 0"/>
    <parent link="link_trunk"/>
    <child link="link_front_left_hip"/>
    <axis xyz="1 0 0"/>
    <limit effort="17" lower="-0.6632" upper="0.6632" velocity="36"/>
  </joint>
  <link name="link_front_left_thigh">
    <inertial>
      <origin rpy="0 0 0" xyz="-0.00615 -0.01668 -0.0405"/>
      <mass value="1.094"/>
      <inertia ixx="6155E-06" ixy="-0.000105" ixz="0.00045" iyy="6140E-06" iyz="-0.000724" izz="805E-06"/>
    </inertial>
    <visual>
      <origin rpy="0 0 0" xyz="0 0 0"/>
      <geometry>
        <mesh filename="package://dobot_hex/meshes/thigh_left.STL"/>
      </geometry>
      <material name="">
        <color rgba="0.752941176470588 0.752941176470588 0.752941176470588 1"/>
      </material>
    </visual>
    <collision>
      <origin rpy="0 1.5708 0" xyz="-0.0225 0 -0.12"/>
      <geometry>
        <box size="0.12 0.024 0.033"/>
      </geometry>
    </collision>
  </link>
  <joint name="joint_front_left_thigh_pitch" type="revolute">
    <origin rpy="0 0 0" xyz="0.0  0.0893 0.0"/>
    <parent link="link_front_left_hip"/>
    <child link="link_front_left_thigh"/>
    <axis xyz="0 1 0"/>
    <limit effort="17" lower="-0.87266" upper="3.14159" velocity="36"/>
  </joint>
  <link name="link_front_left_calf">
    <inertial>
      <origin rpy="0 0 0" xyz="0.00209 0.0 -0.118722"/>
      <mass value="0.145"/>
      <inertia ixx="1143.834E-06" ixy="0.0E-06" ixz="-41.078E-06" iyy="1165.29E-06" iyz="0.0E-06" izz="34.028E-06"/>
    </inertial>
    <visual>
      <origin rpy="0 0 0" xyz="0 0 0"/>
      <geometry>
        <mesh filename="package://dobot_hex/meshes/calf.STL"/>
      </geometry>
      <material name="">
        <color rgba="0.752941176470588 0.752941176470588 0.752941176470588 1"/>
      </material>
    </visual>
    <collision>
      <origin rpy="0 -0.22 0" xyz="0.00 0 -0.06"/>
      <geometry>
        <cylinder length="0.12" radius="0.012"/>
      </geometry>
    </collision>
    <collision>
      <origin rpy="0 0 0" xyz="0.018 0 -0.16"/>
      <geometry>
        <cylinder length="0.065" radius="0.011"/>
      </geometry>
    </collision>
    <!--   <collision>
     <origin rpy="0 0 0" xyz="-0.002 0 -0.22" />
     <geometry>
       <sphere radius="0.022" />
     </geometry>
   </collision>-->
  </link>
  <joint name="joint_front_left_calf_pitch" type="revolute">
    <origin rpy="0 0 0" xyz="0.0 0.0 -0.22"/>
    <parent link="link_front_left_thigh"/>
    <child link="link_front_left_calf"/>
    <axis xyz="0 1 0"/>
    <limit effort="29" lower="-2.7925" upper="-0.5236" velocity="22"/>
  </joint>
  <link name="link_front_left_foot">
    <visual>
      <origin rpy="0 0 0" xyz="0 0 0"/>
      <geometry>
        <sphere radius="0.01"/>
      </geometry>
      <material name="">
        <color rgba="0.752941176470588 0.752941176470588 0.752941176470588 1"/>
      </material>
    </visual>
    <collision>
      <origin rpy="0 0 0" xyz="0 0 0"/>
      <geometry>
        <sphere radius="0.022"/>
      </geometry>
    </collision>
    <inertial>
      <mass value="0.06"/>
      <inertia ixx="9.6e-06" ixy="0.0" ixz="0.0" iyy="9.6e-06" iyz="0.0" izz="9.6e-06"/>
    </inertial>
  </link>
  <joint dont_collapse="true" name="front_left_foot_joint" type="fixed">
    <origin rpy="0 0 0" xyz="-0.002 0 -0.22"/>
    <parent link="link_front_left_calf"/>
    <child link="link_front_left_foot"/>
  </joint>
  <link name="link_front_right_hip">
    <inertial>
      <origin rpy="0 0 0" xyz="-0.00249 -0.00198 0.000018"/>
      <mass value="0.506"/>
      <inertia ixx="162.713E-06" ixy="1.271e-05" ixz="0.0" iyy="293.236E-06" iyz="-0.0" izz="258.577E-06"/>
    </inertial>
    <visual>
      <origin rpy="3.141592653589793 0 0" xyz="0 0 0"/>
      <geometry>
        <mesh filename="package://dobot_hex/meshes/hip.STL"/>
      </geometry>
      <material name="">
        <color rgba="0.752941176470588 0.752941176470588 0.752941176470588 1"/>
      </material>
    </visual>
    <collision>
      <origin rpy="1.5708 0 0" xyz="0 -0.08 0"/>
      <geometry>
        <cylinder length="0.04" radius="0.048"/>
      </geometry>
    </collision>
  </link>
  <joint name="joint_front_right_abad" type="revolute">
    <origin rpy="0 0 0" xyz="0.3003 -0.05 0"/>
    <parent link="link_trunk"/>
    <child link="link_front_right_hip"/>
    <axis xyz="1 0 0"/>
    <limit effort="17" lower="-0.6632" upper="0.6632" velocity="36"/>
  </joint>
  <link name="link_front_right_thigh">
    <inertial>
      <origin rpy="0 0 0" xyz="-0.00615 0.01668 -0.0405"/>
      <mass value="1.094"/>
      <inertia ixx="6155E-06" ixy="0.000105" ixz="0.00045" iyy="6140E-06" iyz="0.000724" izz="805E-06"/>
    </inertial>
    <visual>
      <origin rpy="0 0 0" xyz="0 0 0"/>
      <geometry>
        <mesh filename="package://dobot_hex/meshes/thigh_right.STL"/>
      </geometry>
      <material name="">
        <color rgba="0.752941176470588 0.752941176470588 0.752941176470588 1"/>
      </material>
    </visual>
    <collision>
      <origin rpy="0 1.5708 0" xyz="-0.0225 0 -0.12"/>
      <geometry>
        <box size="0.12 0.024 0.033"/>
      </geometry>
    </collision>
  </link>
  <joint name="joint_front_right_thigh_pitch" type="revolute">
    <origin rpy="0 0 0" xyz="0.0  -0.0893 0.0"/>
    <parent link="link_front_right_hip"/>
    <child link="link_front_right_thigh"/>
    <axis xyz="0 1 0"/>
    <limit effort="17" lower="-0.87266" upper="3.14159" velocity="36"/>
  </joint>
  <link name="link_front_right_calf">
    <inertial>
      <origin rpy="0 0 0" xyz="0.00209 0.0 -0.118722"/>
      <mass value="0.145"/>
      <inertia ixx="1143.834E-06" ixy="0.0E-06" ixz="-41.078E-06" iyy="1165.29E-06" iyz="0.0E-06" izz="34.028E-06"/>
    </inertial>
    <visual>
      <origin rpy="0 0 0" xyz="0 0 0"/>
      <geometry>
        <mesh filename="package://dobot_hex/meshes/calf.STL"/>
      </geometry>
      <material name="">
        <color rgba="0.752941176470588 0.752941176470588 0.752941176470588 1"/>
      </material>
    </visual>
    <collision>
      <origin rpy="0 -0.22 0" xyz="0.00 0 -0.06"/>
      <geometry>
        <cylinder length="0.12" radius="0.012"/>
      </geometry>
    </collision>
    <collision>
      <origin rpy="0 0 0" xyz="0.018 0 -0.16"/>
      <geometry>
        <cylinder length="0.065" radius="0.011"/>
      </geometry>
    </collision>
    <!--   <collision>
     <origin rpy="0 0 0" xyz="-0.002 0 -0.22" />
     <geometry>
       <sphere radius="0.022" />
     </geometry>
   </collision>-->
  </link>
  <joint name="joint_front_right_calf_pitch" type="revolute">
    <origin rpy="0 0 0" xyz="0.0 0.0 -0.22"/>
    <parent link="link_front_right_thigh"/>
    <child link="link_front_right_calf"/>
    <axis xyz="0 1 0"/>
    <limit effort="29" lower="-2.7925" upper="-0.5236" velocity="22"/>
  </joint>
  <link name="link_front_right_foot">
    <visual>
      <origin rpy="0 0 0" xyz="0 0 0"/>
      <geometry>
        <sphere radius="0.01"/>
      </geometry>
      <material name="">
        <color rgba="0.752941176470588 0.752941176470588 0.752941176470588 1"/>
      </material>
    </visual>
    <collision>
      <origin rpy="0 0 0" xyz="0 0 0"/>
      <geometry>
        <sphere radius="0.022"/>
      </geometry>
    </collision>
    <inertial>
      <mass value="0.06"/>
      <inertia ixx="9.6e-06" ixy="0.0" ixz="0.0" iyy="9.6e-06" iyz="0.0" izz="9.6e-06"/>
    </inertial>
  </link>
  <joint dont_collapse="true" name="front_right_foot_joint" type="fixed">
    <origin rpy="0 0 0" xyz="-0.002 0 -0.22"/>
    <parent link="link_front_right_calf"/>
    <child link="link_front_right_foot"/>
  </joint>
  <link name="link_mid_left_hip">
    <inertial>
      <origin rpy="0 0 0" xyz="-0.00249 0.00198 0.000018"/>
      <mass value="0.506"/>
      <inertia ixx="162.713E-06" ixy="-1.271e-05" ixz="0.0" iyy="293.236E-06" iyz="0.0" izz="258.577E-06"/>
    </inertial>
    <visual>
      <origin rpy="0 0 0" xyz="0 0 0"/>
      <geometry>
        <mesh filename="package://dobot_hex/meshes/hip.STL"/>
      </geometry>
      <material name="">
        <color rgba="0.752941176470588 0.752941176470588 0.752941176470588 1"/>
      </material>
    </visual>
    <collision>
      <origin rpy="1.5708 0 0" xyz="0 0.08 0"/>
      <geometry>
        <cylinder length="0.04" radius="0.048"/>
      </geometry>
    </collision>
  </link>
  <joint name="joint_mid_left_abad" type="revolute">
    <origin rpy="0 0 0" xyz="-0.005 0.1275 0"/>
    <parent link="link_trunk"/>
    <child link="link_mid_left_hip"/>
    <axis xyz="1 0 0"/>
    <limit effort="17" lower="-0.6632" upper="0.6632" velocity="36"/>
  </joint>
  <link name="link_mid_left_thigh">
    <inertial>
      <origin rpy="0 0 0" xyz="-0.00615 -0.01668 -0.0405"/>
      <mass value="1.094"/>
      <inertia ixx="6155E-06" ixy="-0.000105" ixz="0.00045" iyy="6140E-06" iyz="-0.000724" izz="805E-06"/>
    </inertial>
    <visual>
      <origin rpy="0 0 0" xyz="0 0 0"/>
      <geometry>
        <mesh filename="package://dobot_hex/meshes/thigh_left.STL"/>
      </geometry>
      <material name="">
        <color rgba="0.752941176470588 0.752941176470588 0.752941176470588 1"/>
      </material>
    </visual>
    <collision>
      <origin rpy="0 1.5708 0" xyz="-0.0225 0 -0.12"/>
      <geometry>
        <box size="0.12 0.024 0.033"/>
      </geometry>
    </collision>
  </link>
  <joint name="joint_mid_left_thigh_pitch" type="revolute">
    <origin rpy="0 0 0" xyz="0.0  0.0893 0.0"/>
    <parent link="link_mid_left_hip"/>
    <child link="link_mid_left_thigh"/>
    <axis xyz="0 1 0"/>
    <limit effort="17" lower="-0.87266" upper="3.14159" velocity="36"/>
  </joint>
  <link name="link_mid_left_calf">
    <inertial>
      <origin rpy="0 0 0" xyz="0.00209 0.0 -0.118722"/>
      <mass value="0.145"/>
      <inertia ixx="1143.834E-06" ixy="0.0E-06" ixz="-41.078E-06" iyy="1165.29E-06" iyz="0.0E-06" izz="34.028E-06"/>
    </inertial>
    <visual>
      <origin rpy="0 0 0" xyz="0 0 0"/>
      <geometry>
        <mesh filename="package://dobot_hex/meshes/calf.STL"/>
      </geometry>
      <material name="">
        <color rgba="0.752941176470588 0.752941176470588 0.752941176470588 1"/>
      </material>
    </visual>
    <collision>
      <origin rpy="0 -0.22 0" xyz="0.00 0 -0.06"/>
      <geometry>
        <cylinder length="0.12" radius="0.012"/>
      </geometry>
    </collision>
    <collision>
      <origin rpy="0 0 0" xyz="0.018 0 -0.16"/>
      <geometry>
        <cylinder length="0.065" radius="0.011"/>
      </geometry>
    </collision>
    <!--   <collision>
     <origin rpy="0 0 0" xyz="-0.002 0 -0.22" />
     <geometry>
       <sphere radius="0.022" />
     </geometry>
   </collision>-->
  </link>
  <joint name="joint_mid_left_calf_pitch" type="revolute">
    <origin rpy="0 0 0" xyz="0.0 0.0 -0.22"/>
    <parent link="link_mid_left_thigh"/>
    <child link="link_mid_left_calf"/>
    <axis xyz="0 1 0"/>
    <limit effort="29" lower="-2.7925" upper="-0.5236" velocity="22"/>
  </joint>
  <link name="link_mid_left_foot">
    <visual>
      <origin rpy="0 0 0" xyz="0 0 0"/>
      <geometry>
        <sphere radius="0.01"/>
      </geometry>
      <material name="">
        <color rgba="0.752941176470588 0.752941176470588 0.752941176470588 1"/>
      </material>
    </visual>
    <collision>
      <origin rpy="0 0 0" xyz="0 0 0"/>
      <geometry>
        <sphere radius="0.022"/>
      </geometry>
    </collision>
    <inertial>
      <mass value="0.06"/>
      <inertia ixx="9.6e-06" ixy="0.0" ixz="0.0" iyy="9.6e-06" iyz="0.0" izz="9.6e-06"/>
    </inertial>
  </link>
  <joint dont_collapse="true" name="mid_left_foot_joint" type="fixed">
    <origin rpy="0 0 0" xyz="-0.002 0 -0.22"/>
    <parent link="link_mid_left_calf"/>
    <child link="link_mid_left_foot"/>
  </joint>
  <link name="link_mid_right_hip">
    <inertial>
      <origin rpy="0 0 0" xyz="-0.00249 -0.00198 0.000018"/>
      <mass value="0.506"/>
      <inertia ixx="162.713E-06" ixy="1.271e-05" ixz="0.0" iyy="293.236E-06" iyz="-0.0" izz="258.577E-06"/>
    </inertial>
    <visual>
      <origin rpy="3.141592653589793 0 0" xyz="0 0 0"/>
      <geometry>
        <mesh filename="package://dobot_hex/meshes/hip.STL"/>
      </geometry>
      <material name="">
        <color rgba="0.752941176470588 0.752941176470588 0.752941176470588 1"/>
      </material>
    </visual>
    <collision>
      <origin rpy="1.5708 0 0" xyz="0 -0.08 0"/>
      <geometry>
        <cylinder length="0.04" radius="0.048"/>
      </geometry>
    </collision>
  </link>
  <joint name="joint_mid_right_abad" type="revolute">
    <origin rpy="0 0 0" xyz="-0.005 -0.1275 0"/>
    <parent link="link_trunk"/>
    <child link="link_mid_right_hip"/>
    <axis xyz="1 0 0"/>
    <limit effort="17" lower="-0.6632" upper="0.6632" velocity="36"/>
  </joint>
  <link name="link_mid_right_thigh">
    <inertial>
      <origin rpy="0 0 0" xyz="-0.00615 0.01668 -0.0405"/>
      <mass value="1.094"/>
      <inertia ixx="6155E-06" ixy="0.000105" ixz="0.00045" iyy="6140E-06" iyz="0.000724" izz="805E-06"/>
    </inertial>
    <visual>
      <origin rpy="0 0 0" xyz="0 0 0"/>
      <geometry>
        <mesh filename="package://dobot_hex/meshes/thigh_right.STL"/>
      </geometry>
      <material name="">
        <color rgba="0.752941176470588 0.752941176470588 0.752941176470588 1"/>
      </material>
    </visual>
    <collision>
      <origin rpy="0 1.5708 0" xyz="-0.0225 0 -0.12"/>
      <geometry>
        <box size="0.12 0.024 0.033"/>
      </geometry>
    </collision>
  </link>
  <joint name="joint_mid_right_thigh_pitch" type="revolute">
    <origin rpy="0 0 0" xyz="0.0  -0.0893 0.0"/>
    <parent link="link_mid_right_hip"/>
    <child link="link_mid_right_thigh"/>
    <axis xyz="0 1 0"/>
    <limit effort="17" lower="-0.87266" upper="3.14159" velocity="36"/>
  </joint>
  <link name="link_mid_right_calf">
    <inertial>
      <origin rpy="0 0 0" xyz="0.00209 0.0 -0.118722"/>
      <mass value="0.145"/>
      <inertia ixx="1143.834E-06" ixy="0.0E-06" ixz="-41.078E-06" iyy="1165.29E-06" iyz="0.0E-06" izz="34.028E-06"/>
    </inertial>
    <visual>
      <origin rpy="0 0 0" xyz="0 0 0"/>
      <geometry>
        <mesh filename="package://dobot_hex/meshes/calf.STL"/>
      </geometry>
      <material name="">
        <color rgba="0.752941176470588 0.752941176470588 0.752941176470588 1"/>
      </material>
    </visual>
    <collision>
      <origin rpy="0 -0.22 0" xyz="0.00 0 -0.06"/>
      <geometry>
        <cylinder length="0.12" radius="0.012"/>
      </geometry>
    </collision>
    <collision>
      <origin rpy="0 0 0" xyz="0.018 0 -0.16"/>
      <geometry>
        <cylinder length="0.065" radius="0.011"/>
      </geometry>
    </collision>
    <!--   <collision>
     <origin rpy="0 0 0" xyz="-0.002 0 -0.22" />
     <geometry>
       <sphere radius="0.022" />
     </geometry>
   </collision>-->
  </link>
  <joint name="joint_mid_right_calf_pitch" type="revolute">
    <origin rpy="0 0 0" xyz="0.0 0.0 -0.22"/>
    <parent link="link_mid_right_thigh"/>
    <child link="link_mid_right_calf"/>
    <axis xyz="0 1 0"/>
    <limit effort="29" lower="-2.7925" upper="-0.5236" velocity="22"/>
  </joint>
  <link name="link_mid_right_foot">
    <visual>
      <origin rpy="0 0 0" xyz="0 0 0"/>
      <geometry>
        <sphere radius="0.01"/>
      </geometry>
      <material name="">
        <color rgba="0.752941176470588 0.752941176470588 0.752941176470588 1"/>
      </material>
    </visual>
    <collision>
      <origin rpy="0 0 0" xyz="0 0 0"/>
      <geometry>
        <sphere radius="0.022"/>
      </geometry>
    </collision>
    <inertial>
      <mass value="0.06"/>
      <inertia ixx="9.6e-06" ixy="0.0" ixz="0.0" iyy="9.6e-06" iyz="0.0" izz="9.6e-06"/>
    </inertial>
  </link>
  <joint dont_collapse="true" name="mid_right_foot_joint" type="fixed">
    <origin rpy="0 0 0" xyz="-0.002 0 -0.22"/>
    <parent link="link_mid_right_calf"/>
    <child link="link_mid_right_foot"/>
  </joint>
  <link name="link_rear_left_hip">
    <inertial>
      <origin rpy="0 0 0" xyz="0.00249 0.00198 0.000018"/>
      <mass value="0.506"/>
      <inertia ixx="162.713E-06" ixy="1.271e-05" ixz="-0.0" iyy="293.236E-06" iyz="0.0" izz="258.577E-06"/>
    </inertial>
    <visual>
      <origin rpy="0 3.141592653589793 0" xyz="0 0 0"/>
      <geometry>
        <mesh filename="package://dobot_hex/meshes/hip.STL"/>
      </geometry>
      <material name="">
        <color rgba="0.752941176470588 0.752941176470588 0.752941176470588 1"/>
      </material>
    </visual>
    <collision>
      <origin rpy="1.5708 0 0" xyz="0 0.08 0"/>
      <geometry>
        <cylinder length="0.04" radius="0.048"/>
      </geometry>
    </collision>
  </link>
  <joint name="joint_rear_left_abad" type="revolute">
    <origin rpy="0 0 0" xyz="-0.3003 0.05 0"/>
    <parent link="link_trunk"/>
    <child link="link_rear_left_hip"/>
    <axis xyz="1 0 0"/>
    <limit effort="17" lower="-0.6632" upper="0.6632" velocity="36"/>
  </joint>
  <link name="link_rear_left_thigh">
    <inertial>
      <origin rpy="0 0 0" xyz="0.00615 -0.01668 -0.0405"/>
      <mass value="1.094"/>
      <inertia ixx="6155E-06" ixy="0.000105" ixz="-0.00045" iyy="6140E-06" iyz="-0.000724" izz="805E-06"/>
    </inertial>
    <visual>
      <origin rpy="0 0 0" xyz="0 0 0"/>
      <geometry>
        <mesh filename="package://dobot_hex/meshes/thigh_left.STL"/>
      </geometry>
      <material name="">
        <color rgba="0.752941176470588 0.752941176470588 0.752941176470588 1"/>
      </material>
    </visual>
    <collision>
      <origin rpy="0 1.5708 0" xyz="-0.0225 0 -0.12"/>
      <geometry>
        <box size="0.12 0.024 0.033"/>
      </geometry>
    </collision>
  </link>
  <joint name="joint_rear_left_thigh_pitch" type="revolute">
    <origin rpy="0 0 0" xyz="-0.0  0.0893 0.0"/>
    <parent link="link_rear_left_hip"/>
    <child link="link_rear_left_thigh"/>
    <axis xyz="0 1 0"/>
    <limit effort="17" lower="-0.87266" upper="4.1713" velocity="37.7"/>
  </joint>
  <link name="link_rear_left_calf">
    <inertial>
      <origin rpy="0 0 0" xyz="0.00209 0.0 -0.118722"/>
      <mass value="0.145"/>
      <inertia ixx="1143.834E-06" ixy="0.0E-06" ixz="-41.078E-06" iyy="1165.29E-06" iyz="0.0E-06" izz="34.028E-06"/>
    </inertial>
    <visual>
      <origin rpy="0 0 0" xyz="0 0 0"/>
      <geometry>
        <mesh filename="package://dobot_hex/meshes/calf.STL"/>
      </geometry>
      <material name="">
        <color rgba="0.752941176470588 0.752941176470588 0.752941176470588 1"/>
      </material>
    </visual>
    <collision>
      <origin rpy="0 -0.22 0" xyz="0.00 0 -0.06"/>
      <geometry>
        <cylinder length="0.12" radius="0.012"/>
      </geometry>
    </collision>
    <collision>
      <origin rpy="0 0 0" xyz="0.018 0 -0.16"/>
      <geometry>
        <cylinder length="0.065" radius="0.011"/>
      </geometry>
    </collision>
    <!--   <collision>
     <origin rpy="0 0 0" xyz="-0.002 0 -0.22" />
     <geometry>
       <sphere radius="0.022" />
     </geometry>
   </collision>-->
  </link>
  <joint name="joint_rear_left_calf_pitch" type="revolute">
    <origin rpy="0 0 0" xyz="0.0 0.0 -0.22"/>
    <parent link="link_rear_left_thigh"/>
    <child link="link_rear_left_calf"/>
    <axis xyz="0 1 0"/>
    <limit effort="29" lower="-2.7925" upper="-0.5236" velocity="22"/>
  </joint>
  <link name="link_rear_left_foot">
    <visual>
      <origin rpy="0 0 0" xyz="0 0 0"/>
      <geometry>
        <sphere radius="0.01"/>
      </geometry>
      <material name="">
        <color rgba="0.752941176470588 0.752941176470588 0.752941176470588 1"/>
      </material>
    </visual>
    <collision>
      <origin rpy="0 0 0" xyz="0 0 0"/>
      <geometry>
        <sphere radius="0.022"/>
      </geometry>
    </collision>
    <inertial>
      <mass value="0.06"/>
      <inertia ixx="9.6e-06" ixy="0.0" ixz="0.0" iyy="9.6e-06" iyz="0.0" izz="9.6e-06"/>
    </inertial>
  </link>
  <joint dont_collapse="true" name="rear_left_foot_joint" type="fixed">
    <origin rpy="0 0 0" xyz="-0.002 0 -0.22"/>
    <parent link="link_rear_left_calf"/>
    <child link="link_rear_left_foot"/>
  </joint>
  <link name="link_rear_right_hip">
    <inertial>
      <origin rpy="0 0 0" xyz="0.00249 -0.00198 0.000018"/>
      <mass value="0.506"/>
      <inertia ixx="162.713E-06" ixy="-1.271e-05" ixz="-0.0" iyy="293.236E-06" iyz="-0.0" izz="258.577E-06"/>
    </inertial>
    <visual>
      <origin rpy="3.141592653589793 3.141592653589793 0" xyz="0 0 0"/>
      <geometry>
        <mesh filename="package://dobot_hex/meshes/hip.STL"/>
      </geometry>
      <material name="">
        <color rgba="0.752941176470588 0.752941176470588 0.752941176470588 1"/>
      </material>
    </visual>
    <collision>
      <origin rpy="1.5708 0 0" xyz="0 -0.08 0"/>
      <geometry>
        <cylinder length="0.04" radius="0.048"/>
      </geometry>
    </collision>
  </link>
  <joint name="joint_rear_right_abad" type="revolute">
    <origin rpy="0 0 0" xyz="-0.3003 -0.05 0"/>
    <parent link="link_trunk"/>
    <child link="link_rear_right_hip"/>
    <axis xyz="1 0 0"/>
    <limit effort="17" lower="-0.6632" upper="0.6632" velocity="36"/>
  </joint>
  <link name="link_rear_right_thigh">
    <inertial>
      <origin rpy="0 0 0" xyz="0.00615 0.01668 -0.0405"/>
      <mass value="1.094"/>
      <inertia ixx="6155E-06" ixy="-0.000105" ixz="-0.00045" iyy="6140E-06" iyz="0.000724" izz="805E-06"/>
    </inertial>
    <visual>
      <origin rpy="0 0 0" xyz="0 0 0"/>
      <geometry>
        <mesh filename="package://dobot_hex/meshes/thigh_right.STL"/>
      </geometry>
      <material name="">
        <color rgba="0.752941176470588 0.752941176470588 0.752941176470588 1"/>
      </material>
    </visual>
    <collision>
      <origin rpy="0 1.5708 0" xyz="-0.0225 0 -0.12"/>
      <geometry>
        <box size="0.12 0.024 0.033"/>
      </geometry>
    </collision>
  </link>
  <joint name="joint_rear_right_thigh_pitch" type="revolute">
    <origin rpy="0 0 0" xyz="-0.0  -0.0893 0.0"/>
    <parent link="link_rear_right_hip"/>
    <child link="link_rear_right_thigh"/>
    <axis xyz="0 1 0"/>
    <limit effort="17" lower="-0.87266" upper="4.1713" velocity="37.7"/>
  </joint>
  <link name="link_rear_right_calf">
    <inertial>
      <origin rpy="0 0 0" xyz="0.00209 0.0 -0.118722"/>
      <mass value="0.145"/>
      <inertia ixx="1143.834E-06" ixy="0.0E-06" ixz="-41.078E-06" iyy="1165.29E-06" iyz="0.0E-06" izz="34.028E-06"/>
    </inertial>
    <visual>
      <origin rpy="0 0 0" xyz="0 0 0"/>
      <geometry>
        <mesh filename="package://dobot_hex/meshes/calf.STL"/>
      </geometry>
      <material name="">
        <color rgba="0.752941176470588 0.752941176470588 0.752941176470588 1"/>
      </material>
    </visual>
    <collision>
      <origin rpy="0 -0.22 0" xyz="0.00 0 -0.06"/>
      <geometry>
        <cylinder length="0.12" radius="0.012"/>
      </geometry>
    </collision>
    <collision>
      <origin rpy="0 0 0" xyz="0.018 0 -0.16"/>
      <geometry>
        <cylinder length="0.065" radius="0.011"/>
      </geometry>
    </collision>
    <!--   <collision>
     <origin rpy="0 0 0" xyz="-0.002 0 -0.22" />
     <geometry>
       <sphere radius="0.022" />
     </geometry>
   </collision>-->
  </link>
  <joint name="joint_rear_right_calf_pitch" type="revolute">
    <origin rpy="0 0 0" xyz="0.0 0.0 -0.22"/>
    <parent link="link_rear_right_thigh"/>
    <child link="link_rear_right_calf"/>
    <axis xyz="0 1 0"/>
    <limit effort="29" lower="-2.7925" upper="-0.5236" velocity="22"/>
  </joint>
  <link name="link_rear_right_foot">
    <visual>
      <origin rpy="0 0 0" xyz="0 0 0"/>
      <geometry>
        <sphere radius="0.01"/>
      </geometry>
      <material name="">
        <color rgba="0.752941176470588 0.752941176470588 0.752941176470588 1"/>
      </material>
    </visual>
    <collision>
      <origin rpy="0 0 0" xyz="0 0 0"/>
      <geometry>
        <sphere radius="0.022"/>
      </geometry>
    </collision>
    <inertial>
      <mass value="0.06"/>
      <inertia ixx="9.6e-06" ixy="0.0" ixz="0.0" iyy="9.6e-06" iyz="0.0" izz="9.6e-06"/>
    </inertial>
  </link>
  <joint dont_collapse="true" name="rear_right_foot_joint" type="fixed">
    <origin rpy="0 0 0" xyz="-0.002 0 -0.22"/>
    <parent link="link_rear_right_calf"/>
    <child link="link_rear_right_foot"/>
  </joint>
</robot>
