<?xml version="1.0" ?>
<!-- =================================================================================== -->
<!-- |    This document was autogenerated by xacro from dobot_quad.xacro               | -->
<!-- |    EDITING THIS FILE BY HAND IS NOT RECOMMENDED                                 | -->
<!-- =================================================================================== -->
<robot name="dobot_quad">
  <mujoco>
    <compiler balanceinertia="true" discardvisual="false" meshdir="../meshes/"/>
  </mujoco>
  <!-- <link name="world">
</link> -->
  <link name="link_trunk">
    <inertial>
      <origin rpy="0 0 0" xyz="0.002447 0.00046 0.002851"/>
      <mass value="10.249"/>
      <inertia ixx="45881.970E-06" ixy="16.957E-06" ixz="177.574E-06" iyy="247797.819E-06" iyz="41.872E-06" izz="268476.829E-06"/>
    </inertial>
    <visual>
      <origin rpy="0 0 0" xyz="0 0 0"/>
      <geometry>
        <mesh filename="package://dobot_quad/meshes/trunk.STL" scale="1 1 1"/>
      </geometry>
      <material name="">
        <color rgba="0.752941176470588 0.752941176470588 0.752941176470588 1"/>
      </material>
    </visual>
    <collision>
      <origin rpy="0 0 0" xyz="0 0 0"/>
      <geometry>
        <box size="0.70 0.18 0.12"/>
      </geometry>
    </collision>
  </link>
  <!-- <joint name="joint_fixed_world" type="floating">
    <origin rpy="0 0 0" xyz="0 0 0.5"/>
    <parent link="world"/>
    <child link="link_trunk"/>
  </joint> -->
  <link name="link_front_left_hip">
    <inertial>
      <origin rpy="0 0 0" xyz="-0.02418 -0.01744 0.0"/>
      <mass value="0.05576"/>
      <inertia ixx="21.088E-06" ixy="1.169e-05" ixz="0.0" iyy="52.90E-06" iyz="0.0" izz="50.03E-06"/>
    </inertial>
    <visual>
      <origin rpy="0 0 0" xyz="0 0 0"/>
      <geometry>
        <mesh filename="package://dobot_quad/meshes/hip.STL" scale="1 1 1"/>
      </geometry>
      <material name="">
        <color rgba="0.752941176470588 0.752941176470588 0.752941176470588 1"/>
      </material>
    </visual>
    <collision>
      <origin rpy="1.5708 0 0" xyz="0 0.08 0"/>
      <geometry>
        <cylinder length="0.04" radius="0.048"/>
      </geometry>
    </collision>
  </link>
  <joint name="joint_front_left_abad" type="revolute">
    <origin rpy="0 0 0" xyz="0.2525 0.07 0"/>
    <parent link="link_trunk"/>
    <child link="link_front_left_hip"/>
    <axis xyz="1 0 0"/>
    <limit effort="23" lower="-0.6632" upper="0.6632" velocity="21"/>
    <armature value="0.01"/>
  </joint>
  <link name="link_front_left_thigh">
    <inertial>
      <origin rpy="0 0 0" xyz="0.00144 -0.04127 -0.02940"/>
      <mass value="1.71551"/>
      <inertia ixx="10737.08420E-06" ixy="-8.637171e-05" ixz="0.00021687284" iyy="8548.74788E-06" iyz="0.00213125546" izz="3618.27220E-06"/>
    </inertial>
    <visual>
      <origin rpy="0 0 0" xyz="0 0 0"/>
      <!-- <geometry>
       <mesh filename="package://dobot_quad/meshes/thigh.STL" scale="1 ${1*y_sign} 1" />
     </geometry> -->
      <geometry>
        <mesh filename="package://dobot_quad/meshes/thigh_l.STL" scale="1 1 1"/>
      </geometry>
      <material name="">
        <color rgba="0.752941176470588 0.752941176470588 0.752941176470588 1"/>
      </material>
    </visual>
    <collision>
      <origin rpy="0 1.5708 0" xyz="0.0 0.0 -0.1075"/>
      <geometry>
        <box size="0.215 0.04 0.06"/>
      </geometry>
    </collision>
  </link>
  <joint name="joint_front_left_thigh_pitch" type="revolute">
    <origin rpy="0 0 0" xyz="0.0  0.08895 0.0"/>
    <parent link="link_front_left_hip"/>
    <child link="link_front_left_thigh"/>
    <axis xyz="0 1 0"/>
    <limit effort="23" lower="-2.618" upper="2.618" velocity="23"/>
    <armature value="0.01"/>
  </joint>
  <link name="link_front_left_calf">
    <inertial>
      <origin rpy="0 0 0" xyz="0.0 0.0 -0.1179"/>
      <mass value="0.278"/>
      <inertia ixx="2802.49E-06" ixy="0.465E-06" ixz="-0.476E-06" iyy="2813.548E-06" iyz="-1.741E-06" izz="65.866E-06"/>
    </inertial>
    <visual>
      <origin rpy="0 0 0" xyz="0 0 0"/>
      <geometry>
        <mesh filename="package://dobot_quad/meshes/calf.STL" scale="1 1 1"/>
      </geometry>
      <material name="">
        <color rgba="0.752941176470588 0.752941176470588 0.752941176470588 1"/>
      </material>
    </visual>
    <collision>
      <origin rpy="0 0 0" xyz="0.0 0.0 -0.12"/>
      <geometry>
        <cylinder length="0.25" radius="0.02"/>
      </geometry>
    </collision>
    <!--   <collision>
     <origin rpy="0 0 0" xyz="0.018 0 -0.16" />
     <geometry>
       <cylinder length="0.065" radius="0.011" />
     </geometry>
   </collision>-->
  </link>
  <joint name="joint_front_left_calf_pitch" type="revolute">
    <origin rpy="0 0 0" xyz="0.0 0.0 -0.215"/>
    <parent link="link_front_left_thigh"/>
    <child link="link_front_left_calf"/>
    <axis xyz="0 1 0"/>
    <limit effort="55" lower="-2.53" upper="2.53" velocity="21"/>
    <armature value="0.025"/>
  </joint>
  <link name="link_front_left_foot">
    <inertial>
      <origin rpy="0 0 0" xyz="0 0 0"/>
      <mass value="0.05"/>
      <inertia ixx="9.6e-06" ixy="0" ixz="0" iyy="9.6e-06" iyz="0" izz="9.6e-06"/>
    </inertial>
    <collision>
      <origin rpy="0 0 0" xyz="0.0 0.0 0.0"/>
      <geometry>
        <sphere radius="0.032"/>
      </geometry>
    </collision>
  </link>
  <joint name="joint_front_left_foot" type="fixed">
    <origin rpy="0 0 0" xyz="0 0 -0.24"/>
    <parent link="link_front_left_calf"/>
    <child link="link_front_left_foot"/>
    <axis xyz="0 0 0"/>
  </joint>
  <link name="link_front_right_hip">
    <inertial>
      <origin rpy="0 0 0" xyz="-0.02418 0.01744 0.0"/>
      <mass value="0.05576"/>
      <inertia ixx="21.088E-06" ixy="-1.169e-05" ixz="0.0" iyy="52.90E-06" iyz="-0.0" izz="50.03E-06"/>
    </inertial>
    <visual>
      <origin rpy="3.141592653589793 0 0" xyz="0 0 0"/>
      <geometry>
        <mesh filename="package://dobot_quad/meshes/hip.STL" scale="1 1 1"/>
      </geometry>
      <material name="">
        <color rgba="0.752941176470588 0.752941176470588 0.752941176470588 1"/>
      </material>
    </visual>
    <collision>
      <origin rpy="1.5708 0 0" xyz="0 -0.08 0"/>
      <geometry>
        <cylinder length="0.04" radius="0.048"/>
      </geometry>
    </collision>
  </link>
  <joint name="joint_front_right_abad" type="revolute">
    <origin rpy="0 0 0" xyz="0.2525 -0.07 0"/>
    <parent link="link_trunk"/>
    <child link="link_front_right_hip"/>
    <axis xyz="1 0 0"/>
    <limit effort="23" lower="-0.6632" upper="0.6632" velocity="21"/>
    <armature value="0.01"/>
  </joint>
  <link name="link_front_right_thigh">
    <inertial>
      <origin rpy="0 0 0" xyz="0.00144 0.04127 -0.02940"/>
      <mass value="1.71551"/>
      <inertia ixx="10737.08420E-06" ixy="8.637171e-05" ixz="0.00021687284" iyy="8548.74788E-06" iyz="-0.00213125546" izz="3618.27220E-06"/>
    </inertial>
    <visual>
      <origin rpy="0 0 0" xyz="0 0 0"/>
      <!-- <geometry>
       <mesh filename="package://dobot_quad/meshes/thigh.STL" scale="1 ${1*y_sign} 1" />
     </geometry> -->
      <geometry>
        <mesh filename="package://dobot_quad/meshes/thigh_r.STL" scale="1 -1 1"/>
      </geometry>
      <material name="">
        <color rgba="0.752941176470588 0.752941176470588 0.752941176470588 1"/>
      </material>
    </visual>
    <collision>
      <origin rpy="0 1.5708 0" xyz="0.0 0.0 -0.1075"/>
      <geometry>
        <box size="0.215 0.04 0.06"/>
      </geometry>
    </collision>
  </link>
  <joint name="joint_front_right_thigh_pitch" type="revolute">
    <origin rpy="0 0 0" xyz="0.0  -0.08895 0.0"/>
    <parent link="link_front_right_hip"/>
    <child link="link_front_right_thigh"/>
    <axis xyz="0 1 0"/>
    <limit effort="23" lower="-2.618" upper="2.618" velocity="23"/>
    <armature value="0.01"/>
  </joint>
  <link name="link_front_right_calf">
    <inertial>
      <origin rpy="0 0 0" xyz="0.0 0.0 -0.1179"/>
      <mass value="0.278"/>
      <inertia ixx="2802.49E-06" ixy="0.465E-06" ixz="-0.476E-06" iyy="2813.548E-06" iyz="-1.741E-06" izz="65.866E-06"/>
    </inertial>
    <visual>
      <origin rpy="0 0 0" xyz="0 0 0"/>
      <geometry>
        <mesh filename="package://dobot_quad/meshes/calf.STL" scale="1 1 1"/>
      </geometry>
      <material name="">
        <color rgba="0.752941176470588 0.752941176470588 0.752941176470588 1"/>
      </material>
    </visual>
    <collision>
      <origin rpy="0 0 0" xyz="0.0 0.0 -0.12"/>
      <geometry>
        <cylinder length="0.25" radius="0.02"/>
      </geometry>
    </collision>
    <!--   <collision>
     <origin rpy="0 0 0" xyz="0.018 0 -0.16" />
     <geometry>
       <cylinder length="0.065" radius="0.011" />
     </geometry>
   </collision>-->
  </link>
  <joint name="joint_front_right_calf_pitch" type="revolute">
    <origin rpy="0 0 0" xyz="0.0 0.0 -0.215"/>
    <parent link="link_front_right_thigh"/>
    <child link="link_front_right_calf"/>
    <axis xyz="0 1 0"/>
    <limit effort="55" lower="-2.53" upper="2.53" velocity="21"/>
    <armature value="0.025"/>
  </joint>
  <link name="link_front_right_foot">
    <inertial>
      <origin rpy="0 0 0" xyz="0 0 0"/>
      <mass value="0.05"/>
      <inertia ixx="9.6e-06" ixy="0" ixz="0" iyy="9.6e-06" iyz="0" izz="9.6e-06"/>
    </inertial>
    <collision>
      <origin rpy="0 0 0" xyz="0.0 0.0 0.0"/>
      <geometry>
        <sphere radius="0.032"/>
      </geometry>
    </collision>
  </link>
  <joint name="joint_front_right_foot" type="fixed">
    <origin rpy="0 0 0" xyz="0 0 -0.24"/>
    <parent link="link_front_right_calf"/>
    <child link="link_front_right_foot"/>
    <axis xyz="0 0 0"/>
  </joint>
  <link name="link_rear_left_hip">
    <inertial>
      <origin rpy="0 0 0" xyz="0.02418 -0.01744 0.0"/>
      <mass value="0.05576"/>
      <inertia ixx="21.088E-06" ixy="-1.169e-05" ixz="-0.0" iyy="52.90E-06" iyz="0.0" izz="50.03E-06"/>
    </inertial>
    <visual>
      <origin rpy="0 3.141592653589793 0" xyz="0 0 0"/>
      <geometry>
        <mesh filename="package://dobot_quad/meshes/hip.STL" scale="1 1 1"/>
      </geometry>
      <material name="">
        <color rgba="0.752941176470588 0.752941176470588 0.752941176470588 1"/>
      </material>
    </visual>
    <collision>
      <origin rpy="1.5708 0 0" xyz="0 0.08 0"/>
      <geometry>
        <cylinder length="0.04" radius="0.048"/>
      </geometry>
    </collision>
  </link>
  <joint name="joint_rear_left_abad" type="revolute">
    <origin rpy="0 0 0" xyz="-0.2525 0.07 0"/>
    <parent link="link_trunk"/>
    <child link="link_rear_left_hip"/>
    <axis xyz="1 0 0"/>
    <limit effort="23" lower="-0.6632" upper="0.6632" velocity="21"/>
    <armature value="0.01"/>
  </joint>
  <link name="link_rear_left_thigh">
    <inertial>
      <origin rpy="0 0 0" xyz="-0.00144 -0.04127 -0.02940"/>
      <mass value="1.71551"/>
      <inertia ixx="10737.08420E-06" ixy="8.637171e-05" ixz="-0.00021687284" iyy="8548.74788E-06" iyz="0.00213125546" izz="3618.27220E-06"/>
    </inertial>
    <visual>
      <origin rpy="0 0 0" xyz="0 0 0"/>
      <!-- <geometry>
       <mesh filename="package://dobot_quad/meshes/thigh.STL" scale="1 ${1*y_sign} 1" />
     </geometry> -->
      <geometry>
        <mesh filename="package://dobot_quad/meshes/thigh_l.STL" scale="1 1 1"/>
      </geometry>
      <material name="">
        <color rgba="0.752941176470588 0.752941176470588 0.752941176470588 1"/>
      </material>
    </visual>
    <collision>
      <origin rpy="0 1.5708 0" xyz="0.0 0.0 -0.1075"/>
      <geometry>
        <box size="0.215 0.04 0.06"/>
      </geometry>
    </collision>
  </link>
  <joint name="joint_rear_left_thigh_pitch" type="revolute">
    <origin rpy="0 0 0" xyz="-0.0  0.08895 0.0"/>
    <parent link="link_rear_left_hip"/>
    <child link="link_rear_left_thigh"/>
    <axis xyz="0 1 0"/>
    <limit effort="23" lower="-2.618" upper="2.618" velocity="21"/>
    <armature value="0.01"/>
  </joint>
  <link name="link_rear_left_calf">
    <inertial>
      <origin rpy="0 0 0" xyz="0.0 0.0 -0.1179"/>
      <mass value="0.278"/>
      <inertia ixx="2802.49E-06" ixy="0.465E-06" ixz="-0.476E-06" iyy="2813.548E-06" iyz="-1.741E-06" izz="65.866E-06"/>
    </inertial>
    <visual>
      <origin rpy="0 0 0" xyz="0 0 0"/>
      <geometry>
        <mesh filename="package://dobot_quad/meshes/calf.STL" scale="1 1 1"/>
      </geometry>
      <material name="">
        <color rgba="0.752941176470588 0.752941176470588 0.752941176470588 1"/>
      </material>
    </visual>
    <collision>
      <origin rpy="0 0 0" xyz="0.0 0.0 -0.12"/>
      <geometry>
        <cylinder length="0.25" radius="0.02"/>
      </geometry>
    </collision>
    <!--   <collision>
     <origin rpy="0 0 0" xyz="0.018 0 -0.16" />
     <geometry>
       <cylinder length="0.065" radius="0.011" />
     </geometry>
   </collision>-->
  </link>
  <joint name="joint_rear_left_calf_pitch" type="revolute">
    <origin rpy="0 0 0" xyz="0.0 0.0 -0.215"/>
    <parent link="link_rear_left_thigh"/>
    <child link="link_rear_left_calf"/>
    <axis xyz="0 1 0"/>
    <limit effort="55" lower="-2.53" upper="2.53" velocity="21"/>
    <armature value="0.025"/>
  </joint>
  <link name="link_rear_left_foot">
    <inertial>
      <origin rpy="0 0 0" xyz="0 0 0"/>
      <mass value="0.05"/>
      <inertia ixx="9.6e-06" ixy="0" ixz="0" iyy="9.6e-06" iyz="0" izz="9.6e-06"/>
    </inertial>
    <collision>
      <origin rpy="0 0 0" xyz="0.0 0.0 0.0"/>
      <geometry>
        <sphere radius="0.032"/>
      </geometry>
    </collision>
  </link>
  <joint name="joint_rear_left_foot" type="fixed">
    <origin rpy="0 0 0" xyz="0 0 -0.24"/>
    <parent link="link_rear_left_calf"/>
    <child link="link_rear_left_foot"/>
    <axis xyz="0 0 0"/>
  </joint>
  <link name="link_rear_right_hip">
    <inertial>
      <origin rpy="0 0 0" xyz="0.02418 0.01744 0.0"/>
      <mass value="0.05576"/>
      <inertia ixx="21.088E-06" ixy="1.169e-05" ixz="-0.0" iyy="52.90E-06" iyz="-0.0" izz="50.03E-06"/>
    </inertial>
    <visual>
      <origin rpy="3.141592653589793 3.141592653589793 0" xyz="0 0 0"/>
      <geometry>
        <mesh filename="package://dobot_quad/meshes/hip.STL" scale="1 1 1"/>
      </geometry>
      <material name="">
        <color rgba="0.752941176470588 0.752941176470588 0.752941176470588 1"/>
      </material>
    </visual>
    <collision>
      <origin rpy="1.5708 0 0" xyz="0 -0.08 0"/>
      <geometry>
        <cylinder length="0.04" radius="0.048"/>
      </geometry>
    </collision>
  </link>
  <joint name="joint_rear_right_abad" type="revolute">
    <origin rpy="0 0 0" xyz="-0.2525 -0.07 0"/>
    <parent link="link_trunk"/>
    <child link="link_rear_right_hip"/>
    <axis xyz="1 0 0"/>
    <limit effort="23" lower="-0.6632" upper="0.6632" velocity="21"/>
    <armature value="0.01"/>
  </joint>
  <link name="link_rear_right_thigh">
    <inertial>
      <origin rpy="0 0 0" xyz="-0.00144 0.04127 -0.02940"/>
      <mass value="1.71551"/>
      <inertia ixx="10737.08420E-06" ixy="-8.637171e-05" ixz="-0.00021687284" iyy="8548.74788E-06" iyz="-0.00213125546" izz="3618.27220E-06"/>
    </inertial>
    <visual>
      <origin rpy="0 0 0" xyz="0 0 0"/>
      <!-- <geometry>
       <mesh filename="package://dobot_quad/meshes/thigh.STL" scale="1 ${1*y_sign} 1" />
     </geometry> -->
      <geometry>
        <mesh filename="package://dobot_quad/meshes/thigh_r.STL" scale="1 -1 1"/>
      </geometry>
      <material name="">
        <color rgba="0.752941176470588 0.752941176470588 0.752941176470588 1"/>
      </material>
    </visual>
    <collision>
      <origin rpy="0 1.5708 0" xyz="0.0 0.0 -0.1075"/>
      <geometry>
        <box size="0.215 0.04 0.06"/>
      </geometry>
    </collision>
  </link>
  <joint name="joint_rear_right_thigh_pitch" type="revolute">
    <origin rpy="0 0 0" xyz="-0.0  -0.08895 0.0"/>
    <parent link="link_rear_right_hip"/>
    <child link="link_rear_right_thigh"/>
    <axis xyz="0 1 0"/>
    <limit effort="23" lower="-2.618" upper="2.618" velocity="21"/>
    <armature value="0.01"/>
  </joint>
  <link name="link_rear_right_calf">
    <inertial>
      <origin rpy="0 0 0" xyz="0.0 0.0 -0.1179"/>
      <mass value="0.278"/>
      <inertia ixx="2802.49E-06" ixy="0.465E-06" ixz="-0.476E-06" iyy="2813.548E-06" iyz="-1.741E-06" izz="65.866E-06"/>
    </inertial>
    <visual>
      <origin rpy="0 0 0" xyz="0 0 0"/>
      <geometry>
        <mesh filename="package://dobot_quad/meshes/calf.STL" scale="1 1 1"/>
      </geometry>
      <material name="">
        <color rgba="0.752941176470588 0.752941176470588 0.752941176470588 1"/>
      </material>
    </visual>
    <collision>
      <origin rpy="0 0 0" xyz="0.0 0.0 -0.12"/>
      <geometry>
        <cylinder length="0.25" radius="0.02"/>
      </geometry>
    </collision>
    <!--   <collision>
     <origin rpy="0 0 0" xyz="0.018 0 -0.16" />
     <geometry>
       <cylinder length="0.065" radius="0.011" />
     </geometry>
   </collision>-->
  </link>
  <joint name="joint_rear_right_calf_pitch" type="revolute">
    <origin rpy="0 0 0" xyz="0.0 0.0 -0.215"/>
    <parent link="link_rear_right_thigh"/>
    <child link="link_rear_right_calf"/>
    <axis xyz="0 1 0"/>
    <limit effort="55" lower="-2.53" upper="2.53" velocity="21"/>
    <armature value="0.025"/>
  </joint>
  <link name="link_rear_right_foot">
    <inertial>
      <origin rpy="0 0 0" xyz="0 0 0"/>
      <mass value="0.05"/>
      <inertia ixx="9.6e-06" ixy="0" ixz="0" iyy="9.6e-06" iyz="0" izz="9.6e-06"/>
    </inertial>
    <collision>
      <origin rpy="0 0 0" xyz="0.0 0.0 0.0"/>
      <geometry>
        <sphere radius="0.032"/>
      </geometry>
    </collision>
  </link>
  <joint name="joint_rear_right_foot" type="fixed">
    <origin rpy="0 0 0" xyz="0 0 -0.24"/>
    <parent link="link_rear_right_calf"/>
    <child link="link_rear_right_foot"/>
    <axis xyz="0 0 0"/>
  </joint>
</robot>
